const x = 10

try {

    x = 10

} catch(err) {
    console.log(`Error ${err}`)
}